<robot name = "robot">
    <link name="1">
        <inertial>
            <origin xyz="0 0 2" rpy="0 0 0"/>
            <mass value="1" />
            <inertia ixx="100" ixy="0" ixz="0" iyy="100" iyz="0" izz="100" />
        </inertial>
        <visual>
            <origin xyz="0 0 2" rpy="0 0 0"/>
            <geometry>
                <box size="1.0069817417380906 1.4966821097652887 1.4363969575324753" />
            </geometry>
            <material name="Cyan">
                <color rgba="0 1.0 1.0 1.0"/>
            </material>
        </visual>
        <collision>
            <origin xyz="0 0 2" rpy="0 0 0"/>
            <geometry>
                <box size="1.0069817417380906 1.4966821097652887 1.4363969575324753" />
            </geometry>
        </collision>
    </link>
    <joint name="1_2" type="revolute">
       <parent link="1"/>
       <child  link="2"/>
       <origin rpy="0 0 0" xyz="-0.5034908708690453 0 2" />
     <axis xyz="0 1 0"/>
       <limit effort="0.0" lower="-3.14159" upper="3.14159" velocity="0.0"/>
    </joint>
    <link name="2">
        <inertial>
            <origin xyz="-0.7435553009692897 0 0" rpy="0 0 0"/>
            <mass value="1" />
            <inertia ixx="100" ixy="0" ixz="0" iyy="100" iyz="0" izz="100" />
        </inertial>
        <visual>
            <origin xyz="-0.7435553009692897 0 0" rpy="0 0 0"/>
            <geometry>
                <box size="1.4871106019385794 1.2717655529693737 0.2930906459242239" />
            </geometry>
            <material name="Sensor">
                <color rgba="0 1.0 0.5 1.0"/>
            </material>
        </visual>
        <collision>
            <origin xyz="-0.7435553009692897 0 0" rpy="0 0 0"/>
            <geometry>
                <box size="1.4871106019385794 1.2717655529693737 0.2930906459242239" />
            </geometry>
        </collision>
    </link>
    <joint name="2_3" type="revolute">
       <parent link="2"/>
       <child  link="3"/>
       <origin rpy="0 0 0" xyz="-1.4871106019385794 0 0" />
     <axis xyz="0 1 0"/>
       <limit effort="0.0" lower="-3.14159" upper="3.14159" velocity="0.0"/>
    </joint>
    <link name="3">
        <inertial>
            <origin xyz="-0.8033521939527302 0 0" rpy="0 0 0"/>
            <mass value="1" />
            <inertia ixx="100" ixy="0" ixz="0" iyy="100" iyz="0" izz="100" />
        </inertial>
        <visual>
            <origin xyz="-0.8033521939527302 0 0" rpy="0 0 0"/>
            <geometry>
                <box size="1.6067043879054603 0.9038779343580464 0.22039244579443762" />
            </geometry>
            <material name="Sensor">
                <color rgba="0 1.0 0.5 1.0"/>
            </material>
        </visual>
        <collision>
            <origin xyz="-0.8033521939527302 0 0" rpy="0 0 0"/>
            <geometry>
                <box size="1.6067043879054603 0.9038779343580464 0.22039244579443762" />
            </geometry>
        </collision>
    </link>
    <joint name="3_4" type="revolute">
       <parent link="3"/>
       <child  link="4"/>
       <origin rpy="0 0 0" xyz="-1.6067043879054603 0 0" />
     <axis xyz="0 1 0"/>
       <limit effort="0.0" lower="-3.14159" upper="3.14159" velocity="0.0"/>
    </joint>
    <link name="4">
        <inertial>
            <origin xyz="-0.5944691017935633 0 0" rpy="0 0 0"/>
            <mass value="1" />
            <inertia ixx="100" ixy="0" ixz="0" iyy="100" iyz="0" izz="100" />
        </inertial>
        <visual>
            <origin xyz="-0.5944691017935633 0 0" rpy="0 0 0"/>
            <geometry>
                <box size="1.1889382035871265 0.9614585015090558 0.43309316685335286" />
            </geometry>
            <material name="Sensor">
                <color rgba="0 1.0 0.5 1.0"/>
            </material>
        </visual>
        <collision>
            <origin xyz="-0.5944691017935633 0 0" rpy="0 0 0"/>
            <geometry>
                <box size="1.1889382035871265 0.9614585015090558 0.43309316685335286" />
            </geometry>
        </collision>
    </link>
    <joint name="1_5" type="revolute">
       <parent link="1"/>
       <child  link="5"/>
       <origin rpy="0 0 0" xyz="0.5034908708690453 0 2" />
     <axis xyz="0 1 0"/>
       <limit effort="0.0" lower="-3.14159" upper="3.14159" velocity="0.0"/>
    </joint>
    <link name="5">
        <inertial>
            <origin xyz="0.5418113193541301 0 0" rpy="0 0 0"/>
            <mass value="1" />
            <inertia ixx="100" ixy="0" ixz="0" iyy="100" iyz="0" izz="100" />
        </inertial>
        <visual>
            <origin xyz="0.5418113193541301 0 0" rpy="0 0 0"/>
            <geometry>
                <box size="1.0836226387082601 0.8218943308363087 0.4569193145999423" />
            </geometry>
            <material name="Sensor">
                <color rgba="0 1.0 0.5 1.0"/>
            </material>
        </visual>
        <collision>
            <origin xyz="0.5418113193541301 0 0" rpy="0 0 0"/>
            <geometry>
                <box size="1.0836226387082601 0.8218943308363087 0.4569193145999423" />
            </geometry>
        </collision>
    </link>
</robot>