<robot name = "robot">
    <link name="1">
        <inertial>
            <origin xyz="0 0 2" rpy="0 0 0"/>
            <mass value="1" />
            <inertia ixx="100" ixy="0" ixz="0" iyy="100" iyz="0" izz="100" />
        </inertial>
        <visual>
            <origin xyz="0 0 2" rpy="0 0 0"/>
            <geometry>
                <box size="1.974847598252965 0.9769830067266513 1.0806697126630531" />
            </geometry>
            <material name="Cyan">
                <color rgba="0 1.0 1.0 1.0"/>
            </material>
        </visual>
        <collision>
            <origin xyz="0 0 2" rpy="0 0 0"/>
            <geometry>
                <box size="1.974847598252965 0.9769830067266513 1.0806697126630531" />
            </geometry>
        </collision>
    </link>
    <joint name="1_3" type="revolute">
       <parent link="1"/>
       <child  link="3"/>
       <origin rpy="0 0 0" xyz="-0.9874237991264825 0 2" />
     <axis xyz="0 1 0"/>
       <limit effort="0.0" lower="-3.14159" upper="3.14159" velocity="0.0"/>
    </joint>
    <link name="3">
        <inertial>
            <origin xyz="-0.7742139376836532 0 0" rpy="0 0 0"/>
            <mass value="1" />
            <inertia ixx="100" ixy="0" ixz="0" iyy="100" iyz="0" izz="100" />
        </inertial>
        <visual>
            <origin xyz="-0.7742139376836532 0 0" rpy="0 0 0"/>
            <geometry>
                <box size="1.5484278753673064 0.9692329860755492 0.4590416349953341" />
            </geometry>
            <material name="Sensor">
                <color rgba="0 1.0 0.5 1.0"/>
            </material>
        </visual>
        <collision>
            <origin xyz="-0.7742139376836532 0 0" rpy="0 0 0"/>
            <geometry>
                <box size="1.5484278753673064 0.9692329860755492 0.4590416349953341" />
            </geometry>
        </collision>
    </link>
    <joint name="3_4" type="revolute">
       <parent link="3"/>
       <child  link="4"/>
       <origin rpy="0 0 0" xyz="-1.5484278753673064 0 0" />
     <axis xyz="0 1 0"/>
       <limit effort="0.0" lower="-3.14159" upper="3.14159" velocity="0.0"/>
    </joint>
    <link name="4">
        <inertial>
            <origin xyz="-0.7579341714939507 0 0" rpy="0 0 0"/>
            <mass value="1" />
            <inertia ixx="100" ixy="0" ixz="0" iyy="100" iyz="0" izz="100" />
        </inertial>
        <visual>
            <origin xyz="-0.7579341714939507 0 0" rpy="0 0 0"/>
            <geometry>
                <box size="1.5158683429879014 1.0627052049178287 0.43001970015891705" />
            </geometry>
            <material name="Cyan">
                <color rgba="0 1.0 1.0 1.0"/>
            </material>
        </visual>
        <collision>
            <origin xyz="-0.7579341714939507 0 0" rpy="0 0 0"/>
            <geometry>
                <box size="1.5158683429879014 1.0627052049178287 0.43001970015891705" />
            </geometry>
        </collision>
    </link>
    <joint name="4_5" type="revolute">
       <parent link="4"/>
       <child  link="5"/>
       <origin rpy="0 0 0" xyz="-0.7579341714939507 0.5313526024589144 -0.10750492503972926" />
     <axis xyz="1 1 0"/>
       <limit effort="0.0" lower="-3.14159" upper="3.14159" velocity="0.0"/>
    </joint>
    <link name="5">
        <inertial>
            <origin xyz="0 0.26745525102773976 0" rpy="0 0 0"/>
            <mass value="1" />
            <inertia ixx="100" ixy="0" ixz="0" iyy="100" iyz="0" izz="100" />
        </inertial>
        <visual>
            <origin xyz="0 0.26745525102773976 0" rpy="0 0 0"/>
            <geometry>
                <box size="1.0390866324173569 0.5349105020554795 0.14979791900573725" />
            </geometry>
            <material name="Cyan">
                <color rgba="0 1.0 1.0 1.0"/>
            </material>
        </visual>
        <collision>
            <origin xyz="0 0.26745525102773976 0" rpy="0 0 0"/>
            <geometry>
                <box size="1.0390866324173569 0.5349105020554795 0.14979791900573725" />
            </geometry>
        </collision>
    </link>
    <joint name="5_6" type="revolute">
       <parent link="5"/>
       <child  link="6"/>
       <origin rpy="0 0 0" xyz="0 0.5349105020554795 -0.03744947975143431" />
     <axis xyz="1 1 0"/>
       <limit effort="0.0" lower="-3.14159" upper="3.14159" velocity="0.0"/>
    </joint>
    <link name="6">
        <inertial>
            <origin xyz="0 0.26745525102773976 0" rpy="0 0 0"/>
            <mass value="1" />
            <inertia ixx="100" ixy="0" ixz="0" iyy="100" iyz="0" izz="100" />
        </inertial>
        <visual>
            <origin xyz="0 0.26745525102773976 0" rpy="0 0 0"/>
            <geometry>
                <box size="1.0390866324173569 0.5349105020554795 0.14979791900573725" />
            </geometry>
            <material name="Sensor">
                <color rgba="0 1.0 0.5 1.0"/>
            </material>
        </visual>
        <collision>
            <origin xyz="0 0.26745525102773976 0" rpy="0 0 0"/>
            <geometry>
                <box size="1.0390866324173569 0.5349105020554795 0.14979791900573725" />
            </geometry>
        </collision>
    </link>
    <joint name="4_7" type="revolute">
       <parent link="4"/>
       <child  link="7"/>
       <origin rpy="0 0 0" xyz="-0.7579341714939507 -0.5313526024589144 -0.10750492503972926" />
     <axis xyz="1 1 0"/>
       <limit effort="0.0" lower="-3.14159" upper="3.14159" velocity="0.0"/>
    </joint>
    <link name="7">
        <inertial>
            <origin xyz="0 -0.26745525102773976 0" rpy="0 0 0"/>
            <mass value="1" />
            <inertia ixx="100" ixy="0" ixz="0" iyy="100" iyz="0" izz="100" />
        </inertial>
        <visual>
            <origin xyz="0 -0.26745525102773976 0" rpy="0 0 0"/>
            <geometry>
                <box size="1.0390866324173569 0.5349105020554795 0.14979791900573725" />
            </geometry>
            <material name="Sensor">
                <color rgba="0 1.0 0.5 1.0"/>
            </material>
        </visual>
        <collision>
            <origin xyz="0 -0.26745525102773976 0" rpy="0 0 0"/>
            <geometry>
                <box size="1.0390866324173569 0.5349105020554795 0.14979791900573725" />
            </geometry>
        </collision>
    </link>
    <joint name="7_8" type="revolute">
       <parent link="7"/>
       <child  link="8"/>
       <origin rpy="0 0 0" xyz="0 -0.5349105020554795 -0.03744947975143431" />
     <axis xyz="1 1 0"/>
       <limit effort="0.0" lower="-3.14159" upper="3.14159" velocity="0.0"/>
    </joint>
    <link name="8">
        <inertial>
            <origin xyz="0 -0.26745525102773976 0" rpy="0 0 0"/>
            <mass value="1" />
            <inertia ixx="100" ixy="0" ixz="0" iyy="100" iyz="0" izz="100" />
        </inertial>
        <visual>
            <origin xyz="0 -0.26745525102773976 0" rpy="0 0 0"/>
            <geometry>
                <box size="1.0390866324173569 0.5349105020554795 0.14979791900573725" />
            </geometry>
            <material name="Sensor">
                <color rgba="0 1.0 0.5 1.0"/>
            </material>
        </visual>
        <collision>
            <origin xyz="0 -0.26745525102773976 0" rpy="0 0 0"/>
            <geometry>
                <box size="1.0390866324173569 0.5349105020554795 0.14979791900573725" />
            </geometry>
        </collision>
    </link>
    <joint name="4_9" type="revolute">
       <parent link="4"/>
       <child  link="9"/>
       <origin rpy="0 0 0" xyz="-1.5158683429879014 0 0" />
     <axis xyz="0 1 0"/>
       <limit effort="0.0" lower="-3.14159" upper="3.14159" velocity="0.0"/>
    </joint>
    <link name="9">
        <inertial>
            <origin xyz="-0.5631286253183454 0 0" rpy="0 0 0"/>
            <mass value="1" />
            <inertia ixx="100" ixy="0" ixz="0" iyy="100" iyz="0" izz="100" />
        </inertial>
        <visual>
            <origin xyz="-0.5631286253183454 0 0" rpy="0 0 0"/>
            <geometry>
                <box size="1.1262572506366908 1.1271208210368409 0.5135969423494512" />
            </geometry>
            <material name="Cyan">
                <color rgba="0 1.0 1.0 1.0"/>
            </material>
        </visual>
        <collision>
            <origin xyz="-0.5631286253183454 0 0" rpy="0 0 0"/>
            <geometry>
                <box size="1.1262572506366908 1.1271208210368409 0.5135969423494512" />
            </geometry>
        </collision>
    </link>
    <joint name="9_10" type="revolute">
       <parent link="9"/>
       <child  link="10"/>
       <origin rpy="0 0 0" xyz="-0.5631286253183454 0.5635604105184204 -0.1283992355873628" />
     <axis xyz="1 1 0"/>
       <limit effort="0.0" lower="-3.14159" upper="3.14159" velocity="0.0"/>
    </joint>
    <link name="10">
        <inertial>
            <origin xyz="0 0.3238168153082781 0" rpy="0 0 0"/>
            <mass value="1" />
            <inertia ixx="100" ixy="0" ixz="0" iyy="100" iyz="0" izz="100" />
        </inertial>
        <visual>
            <origin xyz="0 0.3238168153082781 0" rpy="0 0 0"/>
            <geometry>
                <box size="1.051483675768698 0.6476336306165562 0.2765829210300753" />
            </geometry>
            <material name="Sensor">
                <color rgba="0 1.0 0.5 1.0"/>
            </material>
        </visual>
        <collision>
            <origin xyz="0 0.3238168153082781 0" rpy="0 0 0"/>
            <geometry>
                <box size="1.051483675768698 0.6476336306165562 0.2765829210300753" />
            </geometry>
        </collision>
    </link>
    <joint name="10_11" type="revolute">
       <parent link="10"/>
       <child  link="11"/>
       <origin rpy="0 0 0" xyz="0 0.6476336306165562 -0.06914573025751883" />
     <axis xyz="1 1 0"/>
       <limit effort="0.0" lower="-3.14159" upper="3.14159" velocity="0.0"/>
    </joint>
    <link name="11">
        <inertial>
            <origin xyz="0 0.3238168153082781 0" rpy="0 0 0"/>
            <mass value="1" />
            <inertia ixx="100" ixy="0" ixz="0" iyy="100" iyz="0" izz="100" />
        </inertial>
        <visual>
            <origin xyz="0 0.3238168153082781 0" rpy="0 0 0"/>
            <geometry>
                <box size="1.051483675768698 0.6476336306165562 0.2765829210300753" />
            </geometry>
            <material name="Sensor">
                <color rgba="0 1.0 0.5 1.0"/>
            </material>
        </visual>
        <collision>
            <origin xyz="0 0.3238168153082781 0" rpy="0 0 0"/>
            <geometry>
                <box size="1.051483675768698 0.6476336306165562 0.2765829210300753" />
            </geometry>
        </collision>
    </link>
    <joint name="9_12" type="revolute">
       <parent link="9"/>
       <child  link="12"/>
       <origin rpy="0 0 0" xyz="-0.5631286253183454 -0.5635604105184204 -0.1283992355873628" />
     <axis xyz="1 1 0"/>
       <limit effort="0.0" lower="-3.14159" upper="3.14159" velocity="0.0"/>
    </joint>
    <link name="12">
        <inertial>
            <origin xyz="0 -0.3238168153082781 0" rpy="0 0 0"/>
            <mass value="1" />
            <inertia ixx="100" ixy="0" ixz="0" iyy="100" iyz="0" izz="100" />
        </inertial>
        <visual>
            <origin xyz="0 -0.3238168153082781 0" rpy="0 0 0"/>
            <geometry>
                <box size="1.051483675768698 0.6476336306165562 0.2765829210300753" />
            </geometry>
            <material name="Sensor">
                <color rgba="0 1.0 0.5 1.0"/>
            </material>
        </visual>
        <collision>
            <origin xyz="0 -0.3238168153082781 0" rpy="0 0 0"/>
            <geometry>
                <box size="1.051483675768698 0.6476336306165562 0.2765829210300753" />
            </geometry>
        </collision>
    </link>
    <joint name="12_13" type="revolute">
       <parent link="12"/>
       <child  link="13"/>
       <origin rpy="0 0 0" xyz="0 -0.6476336306165562 -0.06914573025751883" />
     <axis xyz="1 1 0"/>
       <limit effort="0.0" lower="-3.14159" upper="3.14159" velocity="0.0"/>
    </joint>
    <link name="13">
        <inertial>
            <origin xyz="0 -0.3238168153082781 0" rpy="0 0 0"/>
            <mass value="1" />
            <inertia ixx="100" ixy="0" ixz="0" iyy="100" iyz="0" izz="100" />
        </inertial>
        <visual>
            <origin xyz="0 -0.3238168153082781 0" rpy="0 0 0"/>
            <geometry>
                <box size="1.051483675768698 0.6476336306165562 0.2765829210300753" />
            </geometry>
            <material name="Sensor">
                <color rgba="0 1.0 0.5 1.0"/>
            </material>
        </visual>
        <collision>
            <origin xyz="0 -0.3238168153082781 0" rpy="0 0 0"/>
            <geometry>
                <box size="1.051483675768698 0.6476336306165562 0.2765829210300753" />
            </geometry>
        </collision>
    </link>
    <joint name="9_14" type="revolute">
       <parent link="9"/>
       <child  link="14"/>
       <origin rpy="0 0 0" xyz="-1.1262572506366908 0 0" />
     <axis xyz="0 1 0"/>
       <limit effort="0.0" lower="-3.14159" upper="3.14159" velocity="0.0"/>
    </joint>
    <link name="14">
        <inertial>
            <origin xyz="-0.5679513033686006 0 0" rpy="0 0 0"/>
            <mass value="1" />
            <inertia ixx="100" ixy="0" ixz="0" iyy="100" iyz="0" izz="100" />
        </inertial>
        <visual>
            <origin xyz="-0.5679513033686006 0 0" rpy="0 0 0"/>
            <geometry>
                <box size="1.1359026067372011 0.677682478227736 0.33359457020953687" />
            </geometry>
            <material name="Sensor">
                <color rgba="0 1.0 0.5 1.0"/>
            </material>
        </visual>
        <collision>
            <origin xyz="-0.5679513033686006 0 0" rpy="0 0 0"/>
            <geometry>
                <box size="1.1359026067372011 0.677682478227736 0.33359457020953687" />
            </geometry>
        </collision>
    </link>
    <joint name="1_2" type="revolute">
       <parent link="1"/>
       <child  link="2"/>
       <origin rpy="0 0 0" xyz="0.9874237991264825 0 2" />
     <axis xyz="0 1 0"/>
       <limit effort="0.0" lower="-3.14159" upper="3.14159" velocity="0.0"/>
    </joint>
    <link name="2">
        <inertial>
            <origin xyz="0.6135740032833815 0 0" rpy="0 0 0"/>
            <mass value="1" />
            <inertia ixx="100" ixy="0" ixz="0" iyy="100" iyz="0" izz="100" />
        </inertial>
        <visual>
            <origin xyz="0.6135740032833815 0 0" rpy="0 0 0"/>
            <geometry>
                <box size="1.227148006566763 0.9952865733181836 0.4916345470648613" />
            </geometry>
            <material name="Cyan">
                <color rgba="0 1.0 1.0 1.0"/>
            </material>
        </visual>
        <collision>
            <origin xyz="0.6135740032833815 0 0" rpy="0 0 0"/>
            <geometry>
                <box size="1.227148006566763 0.9952865733181836 0.4916345470648613" />
            </geometry>
        </collision>
    </link>
</robot>