<robot name = "robot">
    <link name="1">
        <inertial>
            <origin xyz="0 0 2" rpy="0 0 0"/>
            <mass value="1" />
            <inertia ixx="100" ixy="0" ixz="0" iyy="100" iyz="0" izz="100" />
        </inertial>
        <visual>
            <origin xyz="0 0 2" rpy="0 0 0"/>
            <geometry>
                <box size="1.0678631343578746 1.1463347974848481 1.4613124315551445" />
            </geometry>
            <material name="Cyan">
                <color rgba="0 1.0 1.0 1.0"/>
            </material>
        </visual>
        <collision>
            <origin xyz="0 0 2" rpy="0 0 0"/>
            <geometry>
                <box size="1.0678631343578746 1.1463347974848481 1.4613124315551445" />
            </geometry>
        </collision>
    </link>
    <joint name="1_2" type="revolute">
       <parent link="1"/>
       <child  link="2"/>
       <origin rpy="0 0 0" xyz="0.0 0.5731673987424241 1.6346718921112138" />
     <axis xyz="1 1 0"/>
       <limit effort="0.0" lower="-3.14159" upper="3.14159" velocity="0.0"/>
    </joint>
    <link name="2">
        <inertial>
            <origin xyz="0 0.39804224415057016 0" rpy="0 0 0"/>
            <mass value="1" />
            <inertia ixx="100" ixy="0" ixz="0" iyy="100" iyz="0" izz="100" />
        </inertial>
        <visual>
            <origin xyz="0 0.39804224415057016 0" rpy="0 0 0"/>
            <geometry>
                <box size="1.0147927621608086 0.7960844883011403 0.7992226138411569" />
            </geometry>
            <material name="Cyan">
                <color rgba="0 1.0 1.0 1.0"/>
            </material>
        </visual>
        <collision>
            <origin xyz="0 0.39804224415057016 0" rpy="0 0 0"/>
            <geometry>
                <box size="1.0147927621608086 0.7960844883011403 0.7992226138411569" />
            </geometry>
        </collision>
    </link>
    <joint name="2_3" type="revolute">
       <parent link="2"/>
       <child  link="3"/>
       <origin rpy="0 0 0" xyz="0 0.7960844883011403 -0.19980565346028922" />
     <axis xyz="1 1 0"/>
       <limit effort="0.0" lower="-3.14159" upper="3.14159" velocity="0.0"/>
    </joint>
    <link name="3">
        <inertial>
            <origin xyz="0 0.39804224415057016 0" rpy="0 0 0"/>
            <mass value="1" />
            <inertia ixx="100" ixy="0" ixz="0" iyy="100" iyz="0" izz="100" />
        </inertial>
        <visual>
            <origin xyz="0 0.39804224415057016 0" rpy="0 0 0"/>
            <geometry>
                <box size="1.0147927621608086 0.7960844883011403 0.7992226138411569" />
            </geometry>
            <material name="Sensor">
                <color rgba="0 1.0 0.5 1.0"/>
            </material>
        </visual>
        <collision>
            <origin xyz="0 0.39804224415057016 0" rpy="0 0 0"/>
            <geometry>
                <box size="1.0147927621608086 0.7960844883011403 0.7992226138411569" />
            </geometry>
        </collision>
    </link>
    <joint name="1_4" type="revolute">
       <parent link="1"/>
       <child  link="4"/>
       <origin rpy="0 0 0" xyz="0.0 -0.5731673987424241 1.6346718921112138" />
     <axis xyz="1 1 0"/>
       <limit effort="0.0" lower="-3.14159" upper="3.14159" velocity="0.0"/>
    </joint>
    <link name="4">
        <inertial>
            <origin xyz="0 -0.39804224415057016 0" rpy="0 0 0"/>
            <mass value="1" />
            <inertia ixx="100" ixy="0" ixz="0" iyy="100" iyz="0" izz="100" />
        </inertial>
        <visual>
            <origin xyz="0 -0.39804224415057016 0" rpy="0 0 0"/>
            <geometry>
                <box size="1.0147927621608086 0.7960844883011403 0.7992226138411569" />
            </geometry>
            <material name="Cyan">
                <color rgba="0 1.0 1.0 1.0"/>
            </material>
        </visual>
        <collision>
            <origin xyz="0 -0.39804224415057016 0" rpy="0 0 0"/>
            <geometry>
                <box size="1.0147927621608086 0.7960844883011403 0.7992226138411569" />
            </geometry>
        </collision>
    </link>
    <joint name="4_5" type="revolute">
       <parent link="4"/>
       <child  link="5"/>
       <origin rpy="0 0 0" xyz="0 -0.7960844883011403 -0.19980565346028922" />
     <axis xyz="1 1 0"/>
       <limit effort="0.0" lower="-3.14159" upper="3.14159" velocity="0.0"/>
    </joint>
    <link name="5">
        <inertial>
            <origin xyz="0 -0.39804224415057016 0" rpy="0 0 0"/>
            <mass value="1" />
            <inertia ixx="100" ixy="0" ixz="0" iyy="100" iyz="0" izz="100" />
        </inertial>
        <visual>
            <origin xyz="0 -0.39804224415057016 0" rpy="0 0 0"/>
            <geometry>
                <box size="1.0147927621608086 0.7960844883011403 0.7992226138411569" />
            </geometry>
            <material name="Sensor">
                <color rgba="0 1.0 0.5 1.0"/>
            </material>
        </visual>
        <collision>
            <origin xyz="0 -0.39804224415057016 0" rpy="0 0 0"/>
            <geometry>
                <box size="1.0147927621608086 0.7960844883011403 0.7992226138411569" />
            </geometry>
        </collision>
    </link>
    <joint name="1_6" type="revolute">
       <parent link="1"/>
       <child  link="6"/>
       <origin rpy="0 0 0" xyz="-0.5339315671789373 0 2" />
     <axis xyz="0 1 0"/>
       <limit effort="0.0" lower="-3.14159" upper="3.14159" velocity="0.0"/>
    </joint>
    <link name="6">
        <inertial>
            <origin xyz="-0.7752925865038263 0 0" rpy="0 0 0"/>
            <mass value="1" />
            <inertia ixx="100" ixy="0" ixz="0" iyy="100" iyz="0" izz="100" />
        </inertial>
        <visual>
            <origin xyz="-0.7752925865038263 0 0" rpy="0 0 0"/>
            <geometry>
                <box size="1.5505851730076525 0.8721469829956152 0.45223060138285637" />
            </geometry>
            <material name="Cyan">
                <color rgba="0 1.0 1.0 1.0"/>
            </material>
        </visual>
        <collision>
            <origin xyz="-0.7752925865038263 0 0" rpy="0 0 0"/>
            <geometry>
                <box size="1.5505851730076525 0.8721469829956152 0.45223060138285637" />
            </geometry>
        </collision>
    </link>
    <joint name="6_7" type="revolute">
       <parent link="6"/>
       <child  link="7"/>
       <origin rpy="0 0 0" xyz="-0.7752925865038263 0.4360734914978076 -0.11305765034571409" />
     <axis xyz="1 1 0"/>
       <limit effort="0.0" lower="-3.14159" upper="3.14159" velocity="0.0"/>
    </joint>
    <link name="7">
        <inertial>
            <origin xyz="0 0.279249544368589 0" rpy="0 0 0"/>
            <mass value="1" />
            <inertia ixx="100" ixy="0" ixz="0" iyy="100" iyz="0" izz="100" />
        </inertial>
        <visual>
            <origin xyz="0 0.279249544368589 0" rpy="0 0 0"/>
            <geometry>
                <box size="1.0533773230856256 0.558499088737178 0.13657323805441002" />
            </geometry>
            <material name="Sensor">
                <color rgba="0 1.0 0.5 1.0"/>
            </material>
        </visual>
        <collision>
            <origin xyz="0 0.279249544368589 0" rpy="0 0 0"/>
            <geometry>
                <box size="1.0533773230856256 0.558499088737178 0.13657323805441002" />
            </geometry>
        </collision>
    </link>
    <joint name="7_8" type="revolute">
       <parent link="7"/>
       <child  link="8"/>
       <origin rpy="0 0 0" xyz="0 0.558499088737178 -0.034143309513602504" />
     <axis xyz="1 1 0"/>
       <limit effort="0.0" lower="-3.14159" upper="3.14159" velocity="0.0"/>
    </joint>
    <link name="8">
        <inertial>
            <origin xyz="0 0.279249544368589 0" rpy="0 0 0"/>
            <mass value="1" />
            <inertia ixx="100" ixy="0" ixz="0" iyy="100" iyz="0" izz="100" />
        </inertial>
        <visual>
            <origin xyz="0 0.279249544368589 0" rpy="0 0 0"/>
            <geometry>
                <box size="1.0533773230856256 0.558499088737178 0.13657323805441002" />
            </geometry>
            <material name="Sensor">
                <color rgba="0 1.0 0.5 1.0"/>
            </material>
        </visual>
        <collision>
            <origin xyz="0 0.279249544368589 0" rpy="0 0 0"/>
            <geometry>
                <box size="1.0533773230856256 0.558499088737178 0.13657323805441002" />
            </geometry>
        </collision>
    </link>
    <joint name="6_9" type="revolute">
       <parent link="6"/>
       <child  link="9"/>
       <origin rpy="0 0 0" xyz="-0.7752925865038263 -0.4360734914978076 -0.11305765034571409" />
     <axis xyz="1 1 0"/>
       <limit effort="0.0" lower="-3.14159" upper="3.14159" velocity="0.0"/>
    </joint>
    <link name="9">
        <inertial>
            <origin xyz="0 -0.279249544368589 0" rpy="0 0 0"/>
            <mass value="1" />
            <inertia ixx="100" ixy="0" ixz="0" iyy="100" iyz="0" izz="100" />
        </inertial>
        <visual>
            <origin xyz="0 -0.279249544368589 0" rpy="0 0 0"/>
            <geometry>
                <box size="1.0533773230856256 0.558499088737178 0.13657323805441002" />
            </geometry>
            <material name="Sensor">
                <color rgba="0 1.0 0.5 1.0"/>
            </material>
        </visual>
        <collision>
            <origin xyz="0 -0.279249544368589 0" rpy="0 0 0"/>
            <geometry>
                <box size="1.0533773230856256 0.558499088737178 0.13657323805441002" />
            </geometry>
        </collision>
    </link>
    <joint name="9_10" type="revolute">
       <parent link="9"/>
       <child  link="10"/>
       <origin rpy="0 0 0" xyz="0 -0.558499088737178 -0.034143309513602504" />
     <axis xyz="1 1 0"/>
       <limit effort="0.0" lower="-3.14159" upper="3.14159" velocity="0.0"/>
    </joint>
    <link name="10">
        <inertial>
            <origin xyz="0 -0.279249544368589 0" rpy="0 0 0"/>
            <mass value="1" />
            <inertia ixx="100" ixy="0" ixz="0" iyy="100" iyz="0" izz="100" />
        </inertial>
        <visual>
            <origin xyz="0 -0.279249544368589 0" rpy="0 0 0"/>
            <geometry>
                <box size="1.0533773230856256 0.558499088737178 0.13657323805441002" />
            </geometry>
            <material name="Sensor">
                <color rgba="0 1.0 0.5 1.0"/>
            </material>
        </visual>
        <collision>
            <origin xyz="0 -0.279249544368589 0" rpy="0 0 0"/>
            <geometry>
                <box size="1.0533773230856256 0.558499088737178 0.13657323805441002" />
            </geometry>
        </collision>
    </link>
</robot>