<robot name = "robot">
    <link name="1">
        <inertial>
            <origin xyz="0 0 2" rpy="0 0 0"/>
            <mass value="1" />
            <inertia ixx="100" ixy="0" ixz="0" iyy="100" iyz="0" izz="100" />
        </inertial>
        <visual>
            <origin xyz="0 0 2" rpy="0 0 0"/>
            <geometry>
                <box size="1.3468867510593867 1.4687290897826877 1.3872060036083016" />
            </geometry>
            <material name="Cyan">
                <color rgba="0 1.0 1.0 1.0"/>
            </material>
        </visual>
        <collision>
            <origin xyz="0 0 2" rpy="0 0 0"/>
            <geometry>
                <box size="1.3468867510593867 1.4687290897826877 1.3872060036083016" />
            </geometry>
        </collision>
    </link>
    <joint name="1_3" type="revolute">
       <parent link="1"/>
       <child  link="3"/>
       <origin rpy="0 0 0" xyz="-0.6734433755296934 0 2" />
     <axis xyz="0 1 0"/>
       <limit effort="0.0" lower="-3.14159" upper="3.14159" velocity="0.0"/>
    </joint>
    <link name="3">
        <inertial>
            <origin xyz="-0.8264927621115011 0 0" rpy="0 0 0"/>
            <mass value="1" />
            <inertia ixx="100" ixy="0" ixz="0" iyy="100" iyz="0" izz="100" />
        </inertial>
        <visual>
            <origin xyz="-0.8264927621115011 0 0" rpy="0 0 0"/>
            <geometry>
                <box size="1.6529855242230023 1.11340412546957 0.5918013288350785" />
            </geometry>
            <material name="Cyan">
                <color rgba="0 1.0 1.0 1.0"/>
            </material>
        </visual>
        <collision>
            <origin xyz="-0.8264927621115011 0 0" rpy="0 0 0"/>
            <geometry>
                <box size="1.6529855242230023 1.11340412546957 0.5918013288350785" />
            </geometry>
        </collision>
    </link>
    <joint name="3_4" type="revolute">
       <parent link="3"/>
       <child  link="4"/>
       <origin rpy="0 0 0" xyz="-0.8264927621115011 0.556702062734785 -0.14795033220876963" />
     <axis xyz="1 1 0"/>
       <limit effort="0.0" lower="-3.14159" upper="3.14159" velocity="0.0"/>
    </joint>
    <link name="4">
        <inertial>
            <origin xyz="0 0.22422155603587562 0" rpy="0 0 0"/>
            <mass value="1" />
            <inertia ixx="100" ixy="0" ixz="0" iyy="100" iyz="0" izz="100" />
        </inertial>
        <visual>
            <origin xyz="0 0.22422155603587562 0" rpy="0 0 0"/>
            <geometry>
                <box size="1.0699166946236416 0.44844311207175125 0.2982102450519535" />
            </geometry>
            <material name="Cyan">
                <color rgba="0 1.0 1.0 1.0"/>
            </material>
        </visual>
        <collision>
            <origin xyz="0 0.22422155603587562 0" rpy="0 0 0"/>
            <geometry>
                <box size="1.0699166946236416 0.44844311207175125 0.2982102450519535" />
            </geometry>
        </collision>
    </link>
    <joint name="4_5" type="revolute">
       <parent link="4"/>
       <child  link="5"/>
       <origin rpy="0 0 0" xyz="0 0.44844311207175125 -0.07455256126298837" />
     <axis xyz="1 1 0"/>
       <limit effort="0.0" lower="-3.14159" upper="3.14159" velocity="0.0"/>
    </joint>
    <link name="5">
        <inertial>
            <origin xyz="0 0.22422155603587562 0" rpy="0 0 0"/>
            <mass value="1" />
            <inertia ixx="100" ixy="0" ixz="0" iyy="100" iyz="0" izz="100" />
        </inertial>
        <visual>
            <origin xyz="0 0.22422155603587562 0" rpy="0 0 0"/>
            <geometry>
                <box size="1.0699166946236416 0.44844311207175125 0.2982102450519535" />
            </geometry>
            <material name="Sensor">
                <color rgba="0 1.0 0.5 1.0"/>
            </material>
        </visual>
        <collision>
            <origin xyz="0 0.22422155603587562 0" rpy="0 0 0"/>
            <geometry>
                <box size="1.0699166946236416 0.44844311207175125 0.2982102450519535" />
            </geometry>
        </collision>
    </link>
    <joint name="3_6" type="revolute">
       <parent link="3"/>
       <child  link="6"/>
       <origin rpy="0 0 0" xyz="-0.8264927621115011 -0.556702062734785 -0.14795033220876963" />
     <axis xyz="1 1 0"/>
       <limit effort="0.0" lower="-3.14159" upper="3.14159" velocity="0.0"/>
    </joint>
    <link name="6">
        <inertial>
            <origin xyz="0 -0.22422155603587562 0" rpy="0 0 0"/>
            <mass value="1" />
            <inertia ixx="100" ixy="0" ixz="0" iyy="100" iyz="0" izz="100" />
        </inertial>
        <visual>
            <origin xyz="0 -0.22422155603587562 0" rpy="0 0 0"/>
            <geometry>
                <box size="1.0699166946236416 0.44844311207175125 0.2982102450519535" />
            </geometry>
            <material name="Cyan">
                <color rgba="0 1.0 1.0 1.0"/>
            </material>
        </visual>
        <collision>
            <origin xyz="0 -0.22422155603587562 0" rpy="0 0 0"/>
            <geometry>
                <box size="1.0699166946236416 0.44844311207175125 0.2982102450519535" />
            </geometry>
        </collision>
    </link>
    <joint name="6_7" type="revolute">
       <parent link="6"/>
       <child  link="7"/>
       <origin rpy="0 0 0" xyz="0 -0.44844311207175125 -0.07455256126298837" />
     <axis xyz="1 1 0"/>
       <limit effort="0.0" lower="-3.14159" upper="3.14159" velocity="0.0"/>
    </joint>
    <link name="7">
        <inertial>
            <origin xyz="0 -0.22422155603587562 0" rpy="0 0 0"/>
            <mass value="1" />
            <inertia ixx="100" ixy="0" ixz="0" iyy="100" iyz="0" izz="100" />
        </inertial>
        <visual>
            <origin xyz="0 -0.22422155603587562 0" rpy="0 0 0"/>
            <geometry>
                <box size="1.0699166946236416 0.44844311207175125 0.2982102450519535" />
            </geometry>
            <material name="Sensor">
                <color rgba="0 1.0 0.5 1.0"/>
            </material>
        </visual>
        <collision>
            <origin xyz="0 -0.22422155603587562 0" rpy="0 0 0"/>
            <geometry>
                <box size="1.0699166946236416 0.44844311207175125 0.2982102450519535" />
            </geometry>
        </collision>
    </link>
    <joint name="3_8" type="revolute">
       <parent link="3"/>
       <child  link="8"/>
       <origin rpy="0 0 0" xyz="-1.6529855242230023 0 0" />
     <axis xyz="0 1 0"/>
       <limit effort="0.0" lower="-3.14159" upper="3.14159" velocity="0.0"/>
    </joint>
    <link name="8">
        <inertial>
            <origin xyz="-0.6115916083703753 0 0" rpy="0 0 0"/>
            <mass value="1" />
            <inertia ixx="100" ixy="0" ixz="0" iyy="100" iyz="0" izz="100" />
        </inertial>
        <visual>
            <origin xyz="-0.6115916083703753 0 0" rpy="0 0 0"/>
            <geometry>
                <box size="1.2231832167407506 0.9145799030297643 0.5340343745433296" />
            </geometry>
            <material name="Cyan">
                <color rgba="0 1.0 1.0 1.0"/>
            </material>
        </visual>
        <collision>
            <origin xyz="-0.6115916083703753 0 0" rpy="0 0 0"/>
            <geometry>
                <box size="1.2231832167407506 0.9145799030297643 0.5340343745433296" />
            </geometry>
        </collision>
    </link>
    <joint name="8_9" type="revolute">
       <parent link="8"/>
       <child  link="9"/>
       <origin rpy="0 0 0" xyz="-1.2231832167407506 0 0" />
     <axis xyz="0 1 0"/>
       <limit effort="0.0" lower="-3.14159" upper="3.14159" velocity="0.0"/>
    </joint>
    <link name="9">
        <inertial>
            <origin xyz="-0.9978583874168326 0 0" rpy="0 0 0"/>
            <mass value="1" />
            <inertia ixx="100" ixy="0" ixz="0" iyy="100" iyz="0" izz="100" />
        </inertial>
        <visual>
            <origin xyz="-0.9978583874168326 0 0" rpy="0 0 0"/>
            <geometry>
                <box size="1.9957167748336653 1.0311035543585696 0.48453796470208954" />
            </geometry>
            <material name="Cyan">
                <color rgba="0 1.0 1.0 1.0"/>
            </material>
        </visual>
        <collision>
            <origin xyz="-0.9978583874168326 0 0" rpy="0 0 0"/>
            <geometry>
                <box size="1.9957167748336653 1.0311035543585696 0.48453796470208954" />
            </geometry>
        </collision>
    </link>
    <joint name="1_2" type="revolute">
       <parent link="1"/>
       <child  link="2"/>
       <origin rpy="0 0 0" xyz="0.6734433755296934 0 2" />
     <axis xyz="0 1 0"/>
       <limit effort="0.0" lower="-3.14159" upper="3.14159" velocity="0.0"/>
    </joint>
    <link name="2">
        <inertial>
            <origin xyz="0.6988268680963542 0 0" rpy="0 0 0"/>
            <mass value="1" />
            <inertia ixx="100" ixy="0" ixz="0" iyy="100" iyz="0" izz="100" />
        </inertial>
        <visual>
            <origin xyz="0.6988268680963542 0 0" rpy="0 0 0"/>
            <geometry>
                <box size="1.3976537361927084 0.6160344316030273 0.5953746369070513" />
            </geometry>
            <material name="Sensor">
                <color rgba="0 1.0 0.5 1.0"/>
            </material>
        </visual>
        <collision>
            <origin xyz="0.6988268680963542 0 0" rpy="0 0 0"/>
            <geometry>
                <box size="1.3976537361927084 0.6160344316030273 0.5953746369070513" />
            </geometry>
        </collision>
    </link>
    <joint name="2_10" type="revolute">
       <parent link="2"/>
       <child  link="10"/>
       <origin rpy="0 0 0" xyz="1.3976537361927084 0 0" />
     <axis xyz="0 1 0"/>
       <limit effort="0.0" lower="-3.14159" upper="3.14159" velocity="0.0"/>
    </joint>
    <link name="10">
        <inertial>
            <origin xyz="0.7357843333030656 0 0" rpy="0 0 0"/>
            <mass value="1" />
            <inertia ixx="100" ixy="0" ixz="0" iyy="100" iyz="0" izz="100" />
        </inertial>
        <visual>
            <origin xyz="0.7357843333030656 0 0" rpy="0 0 0"/>
            <geometry>
                <box size="1.4715686666061312 0.7983114739411655 0.5958146288547794" />
            </geometry>
            <material name="Cyan">
                <color rgba="0 1.0 1.0 1.0"/>
            </material>
        </visual>
        <collision>
            <origin xyz="0.7357843333030656 0 0" rpy="0 0 0"/>
            <geometry>
                <box size="1.4715686666061312 0.7983114739411655 0.5958146288547794" />
            </geometry>
        </collision>
    </link>
    <joint name="10_11" type="revolute">
       <parent link="10"/>
       <child  link="11"/>
       <origin rpy="0 0 0" xyz="1.4715686666061312 0 0" />
     <axis xyz="0 1 0"/>
       <limit effort="0.0" lower="-3.14159" upper="3.14159" velocity="0.0"/>
    </joint>
    <link name="11">
        <inertial>
            <origin xyz="0.9286548937040042 0 0" rpy="0 0 0"/>
            <mass value="1" />
            <inertia ixx="100" ixy="0" ixz="0" iyy="100" iyz="0" izz="100" />
        </inertial>
        <visual>
            <origin xyz="0.9286548937040042 0 0" rpy="0 0 0"/>
            <geometry>
                <box size="1.8573097874080085 1.0524582116724508 0.3756277989076362" />
            </geometry>
            <material name="Cyan">
                <color rgba="0 1.0 1.0 1.0"/>
            </material>
        </visual>
        <collision>
            <origin xyz="0.9286548937040042 0 0" rpy="0 0 0"/>
            <geometry>
                <box size="1.8573097874080085 1.0524582116724508 0.3756277989076362" />
            </geometry>
        </collision>
    </link>
    <joint name="11_12" type="revolute">
       <parent link="11"/>
       <child  link="12"/>
       <origin rpy="0 0 0" xyz="0.9286548937040042 0.5262291058362254 -0.09390694972690905" />
     <axis xyz="1 1 0"/>
       <limit effort="0.0" lower="-3.14159" upper="3.14159" velocity="0.0"/>
    </joint>
    <link name="12">
        <inertial>
            <origin xyz="0 0.26601955102213226 0" rpy="0 0 0"/>
            <mass value="1" />
            <inertia ixx="100" ixy="0" ixz="0" iyy="100" iyz="0" izz="100" />
        </inertial>
        <visual>
            <origin xyz="0 0.26601955102213226 0" rpy="0 0 0"/>
            <geometry>
                <box size="1.3332685670691757 0.5320391020442645 0.19367304155640844" />
            </geometry>
            <material name="Sensor">
                <color rgba="0 1.0 0.5 1.0"/>
            </material>
        </visual>
        <collision>
            <origin xyz="0 0.26601955102213226 0" rpy="0 0 0"/>
            <geometry>
                <box size="1.3332685670691757 0.5320391020442645 0.19367304155640844" />
            </geometry>
        </collision>
    </link>
    <joint name="11_13" type="revolute">
       <parent link="11"/>
       <child  link="13"/>
       <origin rpy="0 0 0" xyz="0.9286548937040042 -0.5262291058362254 -0.09390694972690905" />
     <axis xyz="1 1 0"/>
       <limit effort="0.0" lower="-3.14159" upper="3.14159" velocity="0.0"/>
    </joint>
    <link name="13">
        <inertial>
            <origin xyz="0 -0.26601955102213226 0" rpy="0 0 0"/>
            <mass value="1" />
            <inertia ixx="100" ixy="0" ixz="0" iyy="100" iyz="0" izz="100" />
        </inertial>
        <visual>
            <origin xyz="0 -0.26601955102213226 0" rpy="0 0 0"/>
            <geometry>
                <box size="1.3332685670691757 0.5320391020442645 0.19367304155640844" />
            </geometry>
            <material name="Sensor">
                <color rgba="0 1.0 0.5 1.0"/>
            </material>
        </visual>
        <collision>
            <origin xyz="0 -0.26601955102213226 0" rpy="0 0 0"/>
            <geometry>
                <box size="1.3332685670691757 0.5320391020442645 0.19367304155640844" />
            </geometry>
        </collision>
    </link>
</robot>