<robot name = "robot">
    <link name="1">
        <inertial>
            <origin xyz="0 0 2" rpy="0 0 0"/>
            <mass value="1" />
            <inertia ixx="100" ixy="0" ixz="0" iyy="100" iyz="0" izz="100" />
        </inertial>
        <visual>
            <origin xyz="0 0 2" rpy="0 0 0"/>
            <geometry>
                <box size="1.1461751177986281 0.9044457244864212 0.6905678287738731" />
            </geometry>
            <material name="Sensor">
                <color rgba="0 1.0 0.5 1.0"/>
            </material>
        </visual>
        <collision>
            <origin xyz="0 0 2" rpy="0 0 0"/>
            <geometry>
                <box size="1.1461751177986281 0.9044457244864212 0.6905678287738731" />
            </geometry>
        </collision>
    </link>
    <joint name="1_2" type="revolute">
       <parent link="1"/>
       <child  link="2"/>
       <origin rpy="0 0 0" xyz="0.0 0.4522228622432106 1.8273580428065317" />
     <axis xyz="1 1 0"/>
       <limit effort="0.0" lower="-3.14159" upper="3.14159" velocity="0.0"/>
    </joint>
    <link name="2">
        <inertial>
            <origin xyz="0 0.16686341923555975 0" rpy="0 0 0"/>
            <mass value="1" />
            <inertia ixx="100" ixy="0" ixz="0" iyy="100" iyz="0" izz="100" />
        </inertial>
        <visual>
            <origin xyz="0 0.16686341923555975 0" rpy="0 0 0"/>
            <geometry>
                <box size="0.7869228015454138 0.3337268384711195 0.3469319948756061" />
            </geometry>
            <material name="Sensor">
                <color rgba="0 1.0 0.5 1.0"/>
            </material>
        </visual>
        <collision>
            <origin xyz="0 0.16686341923555975 0" rpy="0 0 0"/>
            <geometry>
                <box size="0.7869228015454138 0.3337268384711195 0.3469319948756061" />
            </geometry>
        </collision>
    </link>
    <joint name="2_3" type="revolute">
       <parent link="2"/>
       <child  link="3"/>
       <origin rpy="-45 0 0" xyz="0 0.3337268384711195 -0.08673299871890153" />
     <axis xyz="1 1 0"/>
       <limit effort="0.0" lower="-3.14159" upper="3.14159" velocity="0.0"/>
    </joint>
    <link name="3">
        <inertial>
            <origin xyz="0 0.16686341923555975 0" rpy="0 0 0"/>
            <mass value="1" />
            <inertia ixx="100" ixy="0" ixz="0" iyy="100" iyz="0" izz="100" />
        </inertial>
        <visual>
            <origin xyz="0 0.16686341923555975 0" rpy="0 0 0"/>
            <geometry>
                <box size="0.15738456030908277 0.3337268384711195 0.17346599743780305" />
            </geometry>
            <material name="Sensor">
                <color rgba="0 1.0 0.5 1.0"/>
            </material>
        </visual>
        <collision>
            <origin xyz="0 0.16686341923555975 0" rpy="0 0 0"/>
            <geometry>
                <box size="0.15738456030908277 0.3337268384711195 0.17346599743780305" />
            </geometry>
        </collision>
    </link>
    <joint name="1_4" type="revolute">
       <parent link="1"/>
       <child  link="4"/>
       <origin rpy="0 0 0" xyz="0.0 -0.4522228622432106 1.8273580428065317" />
     <axis xyz="1 1 0"/>
       <limit effort="0.0" lower="-3.14159" upper="3.14159" velocity="0.0"/>
    </joint>
    <link name="4">
        <inertial>
            <origin xyz="0 -0.16686341923555975 0" rpy="0 0 0"/>
            <mass value="1" />
            <inertia ixx="100" ixy="0" ixz="0" iyy="100" iyz="0" izz="100" />
        </inertial>
        <visual>
            <origin xyz="0 -0.16686341923555975 0" rpy="0 0 0"/>
            <geometry>
                <box size="0.7869228015454138 0.3337268384711195 0.3469319948756061" />
            </geometry>
            <material name="Cyan">
                <color rgba="0 1.0 1.0 1.0"/>
            </material>
        </visual>
        <collision>
            <origin xyz="0 -0.16686341923555975 0" rpy="0 0 0"/>
            <geometry>
                <box size="0.7869228015454138 0.3337268384711195 0.3469319948756061" />
            </geometry>
        </collision>
    </link>
    <joint name="4_5" type="revolute">
       <parent link="4"/>
       <child  link="5"/>
       <origin rpy="45 0 0" xyz="0 -0.3337268384711195 -0.08673299871890153" />
     <axis xyz="1 1 0"/>
       <limit effort="0.0" lower="-3.14159" upper="3.14159" velocity="0.0"/>
    </joint>
    <link name="5">
        <inertial>
            <origin xyz="0 -0.16686341923555975 0" rpy="0 0 0"/>
            <mass value="1" />
            <inertia ixx="100" ixy="0" ixz="0" iyy="100" iyz="0" izz="100" />
        </inertial>
        <visual>
            <origin xyz="0 -0.16686341923555975 0" rpy="0 0 0"/>
            <geometry>
                <box size="0.15738456030908277 0.3337268384711195 0.17346599743780305" />
            </geometry>
            <material name="Sensor">
                <color rgba="0 1.0 0.5 1.0"/>
            </material>
        </visual>
        <collision>
            <origin xyz="0 -0.16686341923555975 0" rpy="0 0 0"/>
            <geometry>
                <box size="0.15738456030908277 0.3337268384711195 0.17346599743780305" />
            </geometry>
        </collision>
    </link>
    <joint name="1_6" type="revolute">
       <parent link="1"/>
       <child  link="6"/>
       <origin rpy="0.20052398901919777 0 0.07023048521994799" xyz="0.5730875588993141 0 2" />
     <axis xyz="0 1 0"/>
       <limit effort="0.0" lower="-3.14159" upper="3.14159" velocity="0.0"/>
    </joint>
    <link name="6">
        <inertial>
            <origin xyz="0.5243828337011165 0 0" rpy="0 0 0"/>
            <mass value="1" />
            <inertia ixx="100" ixy="0" ixz="0" iyy="100" iyz="0" izz="100" />
        </inertial>
        <visual>
            <origin xyz="0.5243828337011165 0 0" rpy="0 0 0"/>
            <geometry>
                <box size="1.048765667402233 1.1687671212833426 0.3356447484293533" />
            </geometry>
            <material name="Sensor">
                <color rgba="0 1.0 0.5 1.0"/>
            </material>
        </visual>
        <collision>
            <origin xyz="0.5243828337011165 0 0" rpy="0 0 0"/>
            <geometry>
                <box size="1.048765667402233 1.1687671212833426 0.3356447484293533" />
            </geometry>
        </collision>
    </link>
    <joint name="6_7" type="revolute">
       <parent link="6"/>
       <child  link="7"/>
       <origin rpy="0 0 0.016402351421724904" xyz="1.048765667402233 0 0" />
     <axis xyz="0 1 0"/>
       <limit effort="0.0" lower="-3.14159" upper="3.14159" velocity="0.0"/>
    </joint>
    <link name="7">
        <inertial>
            <origin xyz="0.6030814119371298 0 0" rpy="0 0 0"/>
            <mass value="1" />
            <inertia ixx="100" ixy="0" ixz="0" iyy="100" iyz="0" izz="100" />
        </inertial>
        <visual>
            <origin xyz="0.6030814119371298 0 0" rpy="0 0 0"/>
            <geometry>
                <box size="1.2061628238742597 1.192254274610946 0.5478718335460071" />
            </geometry>
            <material name="Cyan">
                <color rgba="0 1.0 1.0 1.0"/>
            </material>
        </visual>
        <collision>
            <origin xyz="0.6030814119371298 0 0" rpy="0 0 0"/>
            <geometry>
                <box size="1.2061628238742597 1.192254274610946 0.5478718335460071" />
            </geometry>
        </collision>
    </link>
    <joint name="7_8" type="revolute">
       <parent link="7"/>
       <child  link="8"/>
       <origin rpy="0 0.1479099930739915 0.06028086801500576" xyz="1.2061628238742597 0 0" />
     <axis xyz="0 1 0"/>
       <limit effort="0.0" lower="-3.14159" upper="3.14159" velocity="0.0"/>
    </joint>
    <link name="8">
        <inertial>
            <origin xyz="0.942205018649221 0 0" rpy="0 0 0"/>
            <mass value="1" />
            <inertia ixx="100" ixy="0" ixz="0" iyy="100" iyz="0" izz="100" />
        </inertial>
        <visual>
            <origin xyz="0.942205018649221 0 0" rpy="0 0 0"/>
            <geometry>
                <box size="1.884410037298442 0.8510806420637999 0.25898055277132676" />
            </geometry>
            <material name="Cyan">
                <color rgba="0 1.0 1.0 1.0"/>
            </material>
        </visual>
        <collision>
            <origin xyz="0.942205018649221 0 0" rpy="0 0 0"/>
            <geometry>
                <box size="1.884410037298442 0.8510806420637999 0.25898055277132676" />
            </geometry>
        </collision>
    </link>
    <joint name="8_9" type="revolute">
       <parent link="8"/>
       <child  link="9"/>
       <origin rpy="0 0 0" xyz="1.884410037298442 0 0" />
     <axis xyz="0 1 0"/>
       <limit effort="0.0" lower="-3.14159" upper="3.14159" velocity="0.0"/>
    </joint>
    <link name="9">
        <inertial>
            <origin xyz="0.7971246762041405 0 0" rpy="0 0 0"/>
            <mass value="1" />
            <inertia ixx="100" ixy="0" ixz="0" iyy="100" iyz="0" izz="100" />
        </inertial>
        <visual>
            <origin xyz="0.7971246762041405 0 0" rpy="0 0 0"/>
            <geometry>
                <box size="1.594249352408281 1.3036696330348025 0.5878322664553622" />
            </geometry>
            <material name="Cyan">
                <color rgba="0 1.0 1.0 1.0"/>
            </material>
        </visual>
        <collision>
            <origin xyz="0.7971246762041405 0 0" rpy="0 0 0"/>
            <geometry>
                <box size="1.594249352408281 1.3036696330348025 0.5878322664553622" />
            </geometry>
        </collision>
    </link>
</robot>